Workbook

Sheet Employees
A1: EmployeeID | B1: Name | C1: Gender | D1: Age | E1: Birth_date | F1: Department | G1: JobTitle | H1: HireDate | I1: TerminationDate | J1: EmploymentStatus | K1: Manager | L1: Location | M1: PerformanceRating | N1: TrainingHours | O1: SickDays | P1: OvertimeHours
A2: E001 | B2: Employee_1 | C2: M | D2: 23 | E2: 37488 | F2: Finance | G2: Accountant | H2: 42007 | I2: 42426 | J2: Terminated | K2: CEO | L2: Cairo | M2: 5 | N2: 13 | O2: 0 | P2: 1
A3: E002 | B3: Employee_2 | C3: M | D3: 35 | E3: 33171 | F3: HR | G3: HR Specialist | H3: 45110 | I3: 45160 | J3: Terminated | K3: CEO | L3: Giza | M3: 2 | N3: 14 | O3: 9 | P3: 17
A4: E003 | B4: Employee_3 | C4: M | D4: 32 | E4: 34225 | F4: Sales | G4: Sales Manager | H4: 42455 | I4: 43833 | J4: Terminated | K4: Sarah Ahmed | L4: Giza | M4: 1 | N4: 11 | O4: 5 | P4: 38
A5: E004 | B5: Employee_4 | C5: F | D5: 24 | E5: 37166 | F5: Sales | G5: Account Manager | H5: 41201 | J5: Active | K5: Sarah Ahmed | L5: Alexandria | M5: 3 | N5: 26 | O5: 10 | P5: 39
A6: E005 | B6: Employee_5 | C6: F | D6: 33 | E6: 33789 | F6: IT | G6: Data Analyst | H6: 42045 | J6: Active | K6: Mariam Yous | L6: Cairo | M6: 4 | N6: 8 | O6: 7 | P6: 40
A7: E006 | B7: Employee_6 | C7: F | D7: 32 | E7: 33991 | F7: Finance | G7: Finance Manager | H7: 41895 | J7: Active | K7: Sarah Ahmed | L7: Alexandria | M7: 2 | N7: 17 | O7: 3 | P7: 10
A8: E007 | B8: Employee_7 | C8: F | D8: 46 | E8: 29138 | F8: Finance | G8: Financial Analyst | H8: 44741 | J8: Active | K8: Sarah Ahmed | L8: Cairo | M8: 1 | N8: 25 | O8: 5 | P8: 25
A9: E008 | B9: Employee_8 | C9: F | D9: 26 | E9: 36163 | F9: HR | G9: HR Specialist | H9: 42756 | J9: Active | K9: Mona Lotfy | L9: Alexandria | M9: 4 | N9: 4 | O9: 4 | P9: 8
A10: E009 | B10: Employee_9 | C10: M | D10: 38 | E10: 31779 | F10: Marketing | G10: Marketing Manager | H10: 44959 | J10: Active | K10: Mariam Yous | L10: Alexandria | M10: 4 | N10: 2 | O10: 0 | P10: 7
A11: E010 | B11: Employee_10 | C11: M | D11: 32 | E11: 34201 | F11: Sales | G11: Account Manager | H11: 40699 | J11: Active | K11: Mona Lotfy | L11: Alexandria | M11: 3 | N11: 17 | O11: 0 | P11: 7
A12: E011 | B12: Employee_11 | C12: F | D12: 43 | E12: 30215 | F12: IT | G12: Data Scientist | H12: 43740 | I12: 43746 | J12: Terminated | K12: CEO | L12: Cairo | M12: 5 | N12: 29 | O12: 1 | P12: 40
A13: E012 | B13: Employee_12 | C13: F | D13: 54 | E13: 26048 | F13: Marketing | G13: Marketing Specialist | H13: 41431 | J13: Active | K13: CEO | L13: Alexandria | M13: 1 | N13: 19 | O13: 5 | P13: 31
A14: E013 | B14: Employee_13 | C14: M | D14: 29 | E14: 35204 | F14: Finance | G14: Finance Manager | H14: 42140 | I14: 44463 | J14: Terminated | K14: Sarah Ahmed | L14: Alexandria | M14: 4 | N14: 26 | O14: 1 | P14: 34
A15: E014 | B15: Employee_14 | C15: M | D15: 30 | E15: 34992 | F15: Sales | G15: Account Manager | H15: 41531 | I15: 44463 | J15: Terminated | K15: Mona Lotfy | L15: Cairo | M15: 5 | N15: 24 | O15: 3 | P15: 19
A16: E015 | B16: Employee_15 | C16: F | D16: 45 | E16: 29528 | F16: Sales | G16: Account Manager | H16: 43877 | I16: 44463 | J16: Terminated | K16: Mohamed Said | L16: Cairo | M16: 5 | N16: 17 | O16: 3 | P16: 37
A17: E016 | B17: Employee_16 | C17: M | D17: 22 | E17: 37775 | F17: IT | G17: Data Analyst | H17: 42054 | I17: 44463 | J17: Terminated | K17: Sarah Ahmed | L17: Alexandria | M17: 2 | N17: 8 | O17: 10 | P17: 31
A18: E017 | B18: Employee_17 | C18: M | D18: 30 | E18: 34908 | F18: Marketing | G18: SEO Analyst | H18: 44051 | J18: Active | K18: Mona Lotfy | L18: Cairo | M18: 1 | N18: 3 | O18: 10 | P18: 27
A19: E018 | B19: Employee_18 | C19: F | D19: 49 | E19: 28091 | F19: Sales | G19: Sales Manager | H19: 40622 | J19: Active | K19: Sarah Ahmed | L19: Cairo | M19: 4 | N19: 23 | O19: 5 | P19: 6
A20: E019 | B20: Employee_19 | C20: M | D20: 34 | E20: 33396 | F20: HR | G20: HR Specialist | H20: 43854 | I20: 44229 | J20: Terminated | K20: Mona Lotfy | L20: Cairo | M20: 1 | N20: 14 | O20: 8 | P20: 6
A21: E020 | B21: Employee_20 | C21: M | D21: 22 | E21: 37681 | F21: IT | G21: Software Engineer | H21: 41541 | J21: Active | K21: Mariam Yous | L21: Giza | M21: 1 | N21: 5 | O21: 6 | P21: 0
A22: E021 | B22: Employee_21 | C22: F | D22: 38 | E22: 32085 | F22: Sales | G22: Sales Manager | H22: 43644 | J22: Active | K22: Mona Lotfy | L22: Cairo | M22: 2 | N22: 9 | O22: 3 | P22: 3
A23: E022 | B23: Employee_22 | C23: M | D23: 42 | E23: 30519 | F23: IT | G23: Data Analyst | H23: 44964 | J23: Active | K23: Mariam Yous | L23: Cairo | M23: 5 | N23: 2 | O23: 2 | P23: 4
A24: E023 | B24: Employee_23 | C24: M | D24: 37 | E24: 32337 | F24: Sales | G24: Sales Executive | H24: 44845 | J24: Active | K24: Sarah Ahmed | L24: Alexandria | M24: 1 | N24: 13 | O24: 10 | P24: 37
A25: E024 | B25: Employee_24 | C25: F | D25: 38 | E25: 31895 | F25: HR | G25: HR Specialist | H25: 42752 | J25: Active | K25: Mariam Yous | L25: Alexandria | M25: 3 | N25: 14 | O25: 5 | P25: 4
A26: E025 | B26: Employee_25 | C26: M | D26: 51 | E26: 27200 | F26: Marketing | G26: SEO Analyst | H26: 40998 | I26: 42744 | J26: Terminated | K26: Mohamed Said | L26: Cairo | M26: 3 | N26: 28 | O26: 1 | P26: 15
A27: E026 | B27: Employee_26 | C27: F | D27: 40 | E27: 31304 | F27: HR | G27: Recruiter | H27: 44629 | J27: Active | K27: CEO | L27: Cairo | M27: 5 | N27: 9 | O27: 10 | P27: 6
A28: E027 | B28: Employee_27 | C28: M | D28: 38 | E28: 31842 | F28: IT | G28: Data Analyst | H28: 44711 | I28: 44999 | J28: Terminated | K28: Mariam Yous | L28: Alexandria | M28: 3 | N28: 6 | O28: 10 | P28: 40
A29: E028 | B29: Employee_28 | C29: F | D29: 54 | E29: 26106 | F29: Sales | G29: Sales Manager | H29: 40595 | I29: 44064 | J29: Terminated | K29: Sarah Ahmed | L29: Cairo | M29: 3 | N29: 24 | O29: 2 | P29: 40
A30: E029 | B30: Employee_29 | C30: F | D30: 32 | E30: 34051 | F30: Sales | G30: Account Manager | H30: 43682 | J30: Active | K30: Sarah Ahmed | L30: Alexandria | M30: 2 | N30: 17 | O30: 0 | P30: 23
A31: E030 | B31: Employee_30 | C31: M | D31: 49 | E31: 27967 | F31: HR | G31: HR Manager | H31: 42704 | J31: Active | K31: Mohamed Said | L31: Cairo | M31: 2 | N31: 21 | O31: 1 | P31: 22
A32: E031 | B32: Employee_31 | C32: F | D32: 31 | E32: 34343 | F32: HR | G32: HR Manager | H32: 41629 | J32: Active | K32: Mariam Yous | L32: Alexandria | M32: 3 | N32: 25 | O32: 6 | P32: 15
A33: E032 | B33: Employee_32 | C33: F | D33: 32 | E33: 34012 | F33: IT | G33: System Admin | H33: 40496 | J33: Active | K33: Mariam Yous | L33: Giza | M33: 3 | N33: 9 | O33: 3 | P33: 14
A34: E033 | B34: Employee_33 | C34: M | D34: 34 | E34: 33521 | F34: Sales | G34: Sales Manager | H34: 42461 | J34: Active | K34: Mohamed Said | L34: Alexandria | M34: 5 | N34: 12 | O34: 10 | P34: 34
A35: E034 | B35: Employee_34 | C35: F | D35: 23 | E35: 37396 | F35: IT | G35: Data Scientist | H35: 41641 | J35: Active | K35: Sarah Ahmed | L35: Cairo | M35: 5 | N35: 13 | O35: 5 | P35: 20
A36: E035 | B36: Employee_35 | C36: F | D36: 54 | E36: 26293 | F36: IT | G36: System Admin | H36: 44902 | I36: 44924 | J36: Terminated | K36: Sarah Ahmed | L36: Alexandria | M36: 5 | N36: 21 | O36: 10 | P36: 12
A37: E036 | B37: Employee_36 | C37: F | D37: 49 | E37: 27893 | F37: IT | G37: Data Scientist | H37: 45283 | J37: Active | K37: Mohamed Said | L37: Alexandria | M37: 3 | N37: 21 | O37: 6 | P37: 20
A38: E037 | B38: Employee_37 | C38: F | D38: 40 | E38: 31263 | F38: Marketing | G38: Marketing Specialist | H38: 41750 | J38: Active | K38: Mariam Yous | L38: Alexandria | M38: 5 | N38: 9 | O38: 6 | P38: 35
A39: E038 | B39: Employee_38 | C39: M | D39: 41 | E39: 30981 | F39: Finance | G39: Accountant | H39: 43700 | J39: Active | K39: Mohamed Said | L39: Giza | M39: 4 | N39: 14 | O39: 10 | P39: 13
A40: E039 | B40: Employee_39 | C40: F | D40: 32 | E40: 34305 | F40: IT | G40: Data Scientist | H40: 44401 | J40: Active | K40: Mohamed Said | L40: Cairo | M40: 2 | N40: 21 | O40: 4 | P40: 14
...

Sheet SalaryDetails
A1: EmployeeID | B1: BaseSalary | C1: OvertimePay | D1: Deductions | E1: GrossSalary | F1: NetSalary
A2: E001 | B2: 3971 | C2: 50 | D2: 300.73 | E2: 4021 | F2: 3720.27
A3: E002 | B3: 3861 | C3: 850 | D3: 510.27 | E3: 4711 | F3: 4200.73
A4: E003 | B4: 1618 | C4: 1900 | D4: 237.28 | E4: 3518 | F4: 3280.72
A5: E004 | B5: 2750 | C5: 1950 | D5: 313.97 | E5: 4700 | F5: 4386.03
A6: E005 | B6: 1526 | C6: 2000 | D6: 151.16 | E6: 3526 | F6: 3374.84
A7: E006 | B7: 3999 | C7: 500 | D7: 267.23 | E7: 4499 | F7: 4231.77
A8: E007 | B8: 2528 | C8: 1250 | D8: 327.37 | E8: 3778 | F8: 3450.63
A9: E008 | B9: 3244 | C9: 400 | D9: 217.11 | E9: 3644 | F9: 3426.89
A10: E009 | B10: 2098 | C10: 350 | D10: 256.02 | E10: 2448 | F10: 2191.98
A11: E010 | B11: 3640 | C11: 350 | D11: 359.75 | E11: 3990 | F11: 3630.25
A12: E011 | B12: 2278 | C12: 2000 | D12: 322.77 | E12: 4278 | F12: 3955.23
A13: E012 | B13: 1861 | C13: 1550 | D13: 193.94 | E13: 3411 | F13: 3217.06
... A201: E200 | B201: 3533 | C201: 1050 | D201: 417.5 | E201: 4583 | F201: 4165.5

Sheet Sheet1
A1: EmployeeID | B1: TESTT | C1: BaseSalary | D1: TEST | E1: OvertimePay | F1: TESST | G1: Deductions | H1: TTEST | I1: GrossSalary | J1: TESSTT | K1: NetSalary | L1: TOST
A2: E001 | B2: =IF(A2=SalaryDetails!A2,"1","0") -> 1 | C2: 3971 | D2: =IF(C2 = SalaryDetails!B2, "1","0") -> 1 | E2: 50 | F2: =IF(E2=SalaryDetails!C2,"1","0") -> 1 | G2: 300.73001 | H2: =IF(ROUND(G2,2)=SalaryDetails!D2,"1","0") -> 1 | I2: 4021 | J2: =IF(I2 = SalaryDetails!E2,"1","0") -> 1 | K2: 3720.27 | L2: =IF(ROUND(Sheet1!K2,2)=SalaryDetails!F2,"1","0") -> 1
A3: E002 | B3: =IF(A3=SalaryDetails!A3,"1","0") -> 1 | C3: 3861 | D3: =IF(C3 = SalaryDetails!B3, "1","0") -> 1 | E3: 850 | F3: =IF(E3=SalaryDetails!C3,"1","0") -> 1 | G3: 510.26999 | H3: =IF(ROUND(G3,2)=SalaryDetails!D3,"1","0") -> 1 | I3: 4711 | J3: =IF(I3 = SalaryDetails!E3,"1","0") -> 1 | K3: 4200.73 | L3: =IF(ROUND(Sheet1!K3,2)=SalaryDetails!F3,"1","0") -> 1
A4: E003 | B4: =IF(A4=SalaryDetails!A4,"1","0") -> 1 | C4: 1618 | D4: =IF(C4 = SalaryDetails!B4, "1","0") -> 1 | E4: 1900 | F4: =IF(E4=SalaryDetails!C4,"1","0") -> 1 | G4: 237.28 | H4: =IF(ROUND(G4,2)=SalaryDetails!D4,"1","0") -> 1 | I4: 3518 | J4: =IF(I4 = SalaryDetails!E4,"1","0") -> 1 | K4: 3280.72 | L4: =IF(ROUND(Sheet1!K4,2)=SalaryDetails!F4,"1","0") -> 1
A5: E004 | B5: =IF(A5=SalaryDetails!A5,"1","0") -> 1 | C5: 2750 | D5: =IF(C5 = SalaryDetails!B5, "1","0") -> 1 | E5: 1950 | F5: =IF(E5=SalaryDetails!C5,"1","0") -> 1 | G5: 313.97 | H5: =IF(ROUND(G5,2)=SalaryDetails!D5,"1","0") -> 1 | I5: 4700 | J5: =IF(I5 = SalaryDetails!E5,"1","0") -> 1 | K5: 4386.0298 | L5: =IF(ROUND(Sheet1!K5,2)=SalaryDetails!F5,"1","0") -> 1
A6: E005 | B6: =IF(A6=SalaryDetails!A6,"1","0") -> 1 | C6: 1526 | D6: =IF(C6 = SalaryDetails!B6, "1","0") -> 1 | E6: 2000 | F6: =IF(E6=SalaryDetails!C6,"1","0") -> 1 | G6: 151.16 | H6: =IF(ROUND(G6,2)=SalaryDetails!D6,"1","0") -> 1 | I6: 3526 | J6: =IF(I6 = SalaryDetails!E6,"1","0") -> 1 | K6: 3374.8401 | L6: =IF(ROUND(Sheet1!K6,2)=SalaryDetails!F6,"1","0") -> 1
A7: E006 | B7: =IF(A7=SalaryDetails!A7,"1","0") -> 1 | C7: 3999 | D7: =IF(C7 = SalaryDetails!B7, "1","0") -> 1 | E7: 500 | F7: =IF(E7=SalaryDetails!C7,"1","0") -> 1 | G7: 267.23001 | H7: =IF(ROUND(G7,2)=SalaryDetails!D7,"1","0") -> 1 | I7: 4499 | J7: =IF(I7 = SalaryDetails!E7,"1","0") -> 1 | K7: 4231.77 | L7: =IF(ROUND(Sheet1!K7,2)=SalaryDetails!F7,"1","0") -> 1
A8: E007 | B8: =IF(A8=SalaryDetails!A8,"1","0") -> 1 | C8: 2528 | D8: =IF(C8 = SalaryDetails!B8, "1","0") -> 1 | E8: 1250 | F8: =IF(E8=SalaryDetails!C8,"1","0") -> 1 | G8: 327.37 | H8: =IF(ROUND(G8,2)=SalaryDetails!D8,"1","0") -> 1 | I8: 3778 | J8: =IF(I8 = SalaryDetails!E8,"1","0") -> 1 | K8: 3450.6299 | L8: =IF(ROUND(Sheet1!K8,2)=SalaryDetails!F8,"1","0") -> 1
A9: E008 | B9: =IF(A9=SalaryDetails!A9,"1","0") -> 1 | C9: 3244 | D9: =IF(C9 = SalaryDetails!B9, "1","0") -> 1 | E9: 400 | F9: =IF(E9=SalaryDetails!C9,"1","0") -> 1 | G9: 217.11 | H9: =IF(ROUND(G9,2)=SalaryDetails!D9,"1","0") -> 1 | I9: 3644 | J9: =IF(I9 = SalaryDetails!E9,"1","0") -> 1 | K9: 3426.89 | L9: =IF(ROUND(Sheet1!K9,2)=SalaryDetails!F9,"1","0") -> 1
A10: E009 | B10: =IF(A10=SalaryDetails!A10,"1","0") -> 1 | C10: 2098 | D10: =IF(C10 = SalaryDetails!B10, "1","0") -> 1 | E10: 350 | F10: =IF(E10=SalaryDetails!C10,"1","0") -> 1 | G10: 256.01999 | H10: =IF(ROUND(G10,2)=SalaryDetails!D10,"1","0") -> 1 | I10: 2448 | J10: =IF(I10 = SalaryDetails!E10,"1","0") -> 1 | K10: 2191.98 | L10: =IF(ROUND(Sheet1!K10,2)=SalaryDetails!F10,"1","0") -> 1
A11: E010 | B11: =IF(A11=SalaryDetails!A11,"1","0") -> 1 | C11: 3640 | D11: =IF(C11 = SalaryDetails!B11, "1","0") -> 1 | E11: 350 | F11: =IF(E11=SalaryDetails!C11,"1","0") -> 1 | G11: 359.75 | H11: =IF(ROUND(G11,2)=SalaryDetails!D11,"1","0") -> 1 | I11: 3990 | J11: =IF(I11 = SalaryDetails!E11,"1","0") -> 1 | K11: 3630.25 | L11: =IF(ROUND(Sheet1!K11,2)=SalaryDetails!F11,"1","0") -> 1
A12: E011 | B12: =IF(A12=SalaryDetails!A12,"1","0") -> 1 | C12: 2278 | D12: =IF(C12 = SalaryDetails!B12, "1","0") -> 1 | E12: 2000 | F12: =IF(E12=SalaryDetails!C12,"1","0") -> 1 | G12: 322.76999 | H12: =IF(ROUND(G12,2)=SalaryDetails!D12,"1","0") -> 1 | I12: 4278 | J12: =IF(I12 = SalaryDetails!E12,"1","0") -> 1 | K12: 3955.23 | L12: =IF(ROUND(Sheet1!K12,2)=SalaryDetails!F12,"1","0") -> 1
A13: E012 | B13: =IF(A13=SalaryDetails!A13,"1","0") -> 1 | C13: 1861 | D13: =IF(C13 = SalaryDetails!B13, "1","0") -> 1 | E13: 1550 | F13: =IF(E13=SalaryDetails!C13,"1","0") -> 1 | G13: 193.94 | H13: =IF(ROUND(G13,2)=SalaryDetails!D13,"1","0") -> 1 | I13: 3411 | J13: =IF(I13 = SalaryDetails!E13,"1","0") -> 1 | K13: 3217.0601 | L13: =IF(ROUND(Sheet1!K13,2)=SalaryDetails!F13,"1","0") -> 1
... A138: E137 | B138: =IF(A138=SalaryDetails!A138,"1","0") -> 1 | C138: 1476 | D138: =IF(C138 = SalaryDetails!B138, "1","0") -> 1 | E138: 93.360107 | F138: =IF(E138=SalaryDetails!C138,"1","0") -> 0 | G138: 863.27979 | H138: =IF(ROUND(G138,2)=SalaryDetails!D138,"1","0") -> 0 | I138: 2526 | J138: =IF(I138 = SalaryDetails!E138,"1","0") -> 1 | K138: 2432.6399 | L138: =IF(ROUND(Sheet1!K138,2)=SalaryDetails!F138,"1","0") -> 1
A139: E138 | B139: =IF(A139=SalaryDetails!A139,"1","0") -> 1 | C139: 1917 | D139: 1 | E139: 400 | F139: =IF(E139=SalaryDetails!C139,"1","0") -> 1 | G139: 131.77 | H139: =IF(ROUND(G139,2)=SalaryDetails!D139,"1","0") -> 1 | I139: 2317 | J139: =IF(I139 = SalaryDetails!E139,"1","0") -> 0 | K139: 2185.23 | L139: =IF(ROUND(Sheet1!K139,2)=SalaryDetails!F139,"1","0") -> 1
A140: E139 | B140: =IF(A140=SalaryDetails!A140,"1","0") -> 1 | C140: 1371 | D140: =IF(C140 = SalaryDetails!B140, "1","0") -> 1 | E140: 1500 | F140: =IF(E140=SalaryDetails!C140,"1","0") -> 1 | G140: 130.09 | H140: =IF(ROUND(G140,2)=SalaryDetails!D140,"1","0") -> 1 | I140: 2871 | J140: =IF(I140 = SalaryDetails!E140,"1","0") -> 1 | K140: 2740.9099 | L140: =IF(ROUND(Sheet1!K140,2)=SalaryDetails!F140,"1","0") -> 1
A141: E140 | B141: =IF(A141=SalaryDetails!A141,"1","0") -> 1 | C141: 1395 | D141: =IF(C141 = SalaryDetails!B141, "1","0") -> 1 | E141: 1350 | F141: =IF(E141=SalaryDetails!C141,"1","0") -> 1 | G141: 147.14 | H141: =IF(ROUND(G141,2)=SalaryDetails!D141,"1","0") -> 1 | I141: 2745 | J141: =IF(I141 = SalaryDetails!E141,"1","0") -> 1 | K141: 2597.8601 | L141: =IF(ROUND(Sheet1!K141,2)=SalaryDetails!F141,"1","0") -> 1
A142: E141 | B142: =IF(A142=SalaryDetails!A142,"1","0") -> 1 | C142: 3237 | D142: =IF(C142 = SalaryDetails!B142, "1","0") -> 1 | E142: 1350 | F142: =IF(E142=SalaryDetails!C142,"1","0") -> 1 | G142: 293.92999 | H142: =IF(ROUND(G142,2)=SalaryDetails!D142,"1","0") -> 1 | I142: 4587 | J142: =IF(I142 = SalaryDetails!E142,"1","0") -> 1 | K142: 4293.0698 | L142: =IF(ROUND(Sheet1!K142,2)=SalaryDetails!F142,"1","0") -> 1
A143: E142 | B143: =IF(A143=SalaryDetails!A143,"1","0") -> 1 | C143: 1620 | D143: =IF(C143 = SalaryDetails!B143, "1","0") -> 1 | E143: 1900 | F143: =IF(E143=SalaryDetails!C143,"1","0") -> 1 | G143: 85.25 | H143: =IF(ROUND(G143,2)=SalaryDetails!D143,"1","0") -> 1 | I143: 3520 | J143: =IF(I143 = SalaryDetails!E143,"1","0") -> 1 | K143: 3434.75 | L143: =IF(ROUND(Sheet1!K143,2)=SalaryDetails!F143,"1","0") -> 1
A144: E143 | B144: =IF(A144=SalaryDetails!A144,"1","0") -> 1 | C144: 3718 | D144: =IF(C144 = SalaryDetails!B144, "1","0") -> 1 | E144: 2000 | F144: =IF(E144=SalaryDetails!C144,"1","0") -> 1 | G144: 317.48999 | H144: =IF(ROUND(G144,2)=SalaryDetails!D144,"1","0") -> 1 | I144: 5718 | J144: =IF(I144 = SalaryDetails!E144,"1","0") -> 1 | K144: 5400.5098 | L144: =IF(ROUND(Sheet1!K144,2)=SalaryDetails!F144,"1","0") -> 1
A145: E144 | B145: =IF(A145=SalaryDetails!A145,"1","0") -> 1 | C145: 1784 | D145: =IF(C145 = SalaryDetails!B145, "1","0") -> 1 | E145: 200 | F145: =IF(E145=SalaryDetails!C145,"1","0") -> 1 | G145: 105.8 | H145: =IF(ROUND(G145,2)=SalaryDetails!D145,"1","0") -> 1 | I145: 1984 | J145: =IF(I145 = SalaryDetails!E145,"1","0") -> 1 | K145: 1878.2 | L145: =IF(ROUND(Sheet1!K145,2)=SalaryDetails!F145,"1","0") -> 1
A146: E145 | B146: =IF(A146=SalaryDetails!A146,"1","0") -> 1 | C146: 3981 | D146: =IF(C146 = SalaryDetails!B146, "1","0") -> 1 | E146: 1800 | F146: =IF(E146=SalaryDetails!C146,"1","0") -> 1 | G146: 437.13 | H146: =IF(ROUND(G146,2)=SalaryDetails!D146,"1","0") -> 1 | I146: 5781 | J146: =IF(I146 = SalaryDetails!E146,"1","0") -> 1 | K146: 5343.8701 | L146: =IF(ROUND(Sheet1!K146,2)=SalaryDetails!F146,"1","0") -> 1
A147: E146 | B147: =IF(A147=SalaryDetails!A147,"1","0") -> 1 | C147: 2222 | D147: =IF(C147 = SalaryDetails!B147, "1","0") -> 1 | E147: 1200 | F147: =IF(E147=SalaryDetails!C147,"1","0") -> 1 | G147: 183.19 | H147: =IF(ROUND(G147,2)=SalaryDetails!D147,"1","0") -> 1 | I147: 3422 | J147: =IF(I147 = SalaryDetails!E147,"1","0") -> 1 | K147: 3238.8101 | L147: =IF(ROUND(Sheet1!K147,2)=SalaryDetails!F147,"1","0") -> 1
A148: E147 | B148: =IF(A148=SalaryDetails!A148,"1","0") -> 1 | C148: 3706 | D148: =IF(C148 = SalaryDetails!B148, "1","0") -> 1 | E148: 400 | F148: =IF(E148=SalaryDetails!C148,"1","0") -> 1 | G148: 328.07001 | H148: =IF(ROUND(G148,2)=SalaryDetails!D148,"1","0") -> 1 | I148: 4106 | J148: =IF(I148 = SalaryDetails!E148,"1","0") -> 1 | K148: 3777.9299 | L148: =IF(ROUND(Sheet1!K148,2)=SalaryDetails!F148,"1","0") -> 1
A149: E148 | B149: =IF(A149=SalaryDetails!A149,"1","0") -> 1 | C149: 3993 | D149: =IF(C149 = SalaryDetails!B149, "1","0") -> 1 | E149: 1750 | F149: =IF(E149=SalaryDetails!C149,"1","0") -> 1 | G149: 316.17999 | H149: =IF(ROUND(G149,2)=SalaryDetails!D149,"1","0") -> 1 | I149: 5743 | J149: =IF(I149 = SalaryDetails!E149,"1","0") -> 1 | K149: 5426.8198 | L149: =IF(ROUND(Sheet1!K149,2)=SalaryDetails!F149,"1","0") -> 1
A150: E149 | B150: =IF(A150=SalaryDetails!A150,"1","0") -> 1 | C150: 3283 | D150: =IF(C150 = SalaryDetails!B150, "1","0") -> 1 | E150: 750 | F150: =IF(E150=SalaryDetails!C150,"1","0") -> 1 | G150: 291.45999 | H150: =IF(ROUND(G150,2)=SalaryDetails!D150,"1","0") -> 1 | I150: 4033 | J150: =IF(I150 = SalaryDetails!E150,"1","0") -> 1 | K150: 3741.54 | L150: =IF(ROUND(Sheet1!K150,2)=SalaryDetails!F150,"1","0") -> 1
A151: E150 | B151: =IF(A151=SalaryDetails!A151,"1","0") -> 1 | C151: 3459 | D151: =IF(C151 = SalaryDetails!B151, "1","0") -> 1 | E151: 1250 | F151: =IF(E151=SalaryDetails!C151,"1","0") -> 1 | G151: 202.25 | H151: =IF(ROUND(G151,2)=SalaryDetails!D151,"1","0") -> 1 | I151: 4709 | J151: =IF(I151 = SalaryDetails!E151,"1","0") -> 1 | K151: 4506.75 | L151: =IF(ROUND(Sheet1!K151,2)=SalaryDetails!F151,"1","0") -> 1
... A201: E200 | B201: =IF(A201=SalaryDetails!A201,"1","0") -> 1 | C201: 3533 | D201: =IF(C201 = SalaryDetails!B201, "1","0") -> 1 | E201: 1050 | F201: =IF(E201=SalaryDetails!C201,"1","0") -> 1 | G201: 417.5 | H201: =IF(ROUND(G201,2)=SalaryDetails!D201,"1","0") -> 1 | I201: 4583 | J201: =IF(I201 = SalaryDetails!E201,"1","0") -> 1 | K201: 4165.5 | L201: =IF(ROUND(Sheet1!K201,2)=SalaryDetails!F201,"1","0") -> 1
E209: 188-50
E210: 1150-359
